Workbook

Sheet Inputs
A1: GenAI FinOps — three-year TCO of the underwriting assistant
A2: Every blue cell is an input. Change one and the whole workbook recalculates. Black cells are formulas.
A4: Use case — underwriting assistant
A5: Intended users | B5: 300 | C5: people | D5: Chapter 5.3; assumption for a mid-sized Swiss insurer
A6: Tasks per user per working day | B6: 20 | C6: tasks | D6: Chapter 5.3
A7: Input tokens per task | B7: 5000 | C7: tokens | D7: Chapter 5.3 / Annex F.3
A8: Output tokens per task | B8: 1000 | C8: tokens | D8: Chapter 5.3 / Annex F.3
A9: Working days per month | B9: 22 | C9: days | D9: Annex F.3
A10: Working seconds per day | B10: 28800 | C10: s | D10: Annex F.3 — eight hours
A11: Peak factor, busiest hour | B11: 3 | C11: x | D11: Annex F.3
A12: Horizon | B12: 36 | C12: months | D12: Annex F.2 — matches Azure reservation and APEX terms
A14: Adoption — Bass diffusion
A15: p, coefficient of innovation | B15: 0.03 | C15: per quarter | D15: Annex F.2; Sultan et al. meta-analysis [51]
A16: q, coefficient of imitation | B16: 0.38 | C16: per quarter | D16: Annex F.2; Sultan et al. meta-analysis [51]
A18: AI as a Service — Microsoft Copilot
A19: Microsoft 365 Copilot seat | B19: 25 | C19: CHF/user/mo | D19: Annex B.1 — USD 30 converted at 0.8321 (Annex G.1)
A20: Copilot Credits per answer | B20: 10 | C20: credits | D20: Annex B.2, Table B1 — 2 = generative answer; 10 = tenant-graph grounding
A21: Credits per capacity pack | B21: 25000 | C21: credits | D21: Annex B.1
A22: Price per capacity pack | B22: 166 | C22: CHF/mo | D22: Annex B.1 — USD 200
A24: GenAI Gateway — Microsoft Foundry, GPT-5.4
A25: Input price | B25: 2.08 | C25: CHF/M tokens | D25: Annex A.3, ref [37]
A26: Output price | B26: 12.48 | C26: CHF/M tokens | D26: Annex A.3, ref [37]
A28: Hyperscaled and Owned AI — Tier 2 GPU
A29: Azure NC80adis H100 v5, always on | B29: 12126 | C29: CHF/mo | D29: Annex G.2 — 730 h, Switzerland North, list price
A30: Throughput per VM | B30: 2400 | C30: tokens/s | D30: Annex G / estimator
A31: Price per H100 NVL card | B31: 29000 | C31: USD | D31: TRG Datacenters via IntuitionLabs, 10 Oct 2026 — no NVIDIA list price exists
A32: GPUs per server | B32: 2 | C32: cards | D32: Annex D.2, Table D1 — PowerEdge R760xa, Tier 2
A33: Server without GPUs | B33: 30000 | C33: USD | D33: ESTIMATE — 2U dual-socket chassis, CPUs, RAM, NVMe, NICs
A34: USD to CHF | B34: 0.8321 | C34: CHF/USD | D34: Annex G.1, ref [52] — mid rate 12 Oct 2026
A35: APEX subscription uplift over purchase | B35: 1.4 | C35: x | D35: ASSUMPTION — 3-year hardware-as-a-service typically 1.3-1.6x purchase; Dell quotes per customer
A36: Power draw under load | B36: 1.6 | C36: kW | D36: 2 x H100 NVL at 400 W plus host
A37: Electricity | B37: 0.2 | C37: CHF/kWh | D37: ESTIMATE — Swiss commercial rate 2026
A38: Swisscom colocation | B38: 1250 | C38: CHF/rack/mo | D38: Annex D.1, ref [50]
A39: Owned AI cost per GPU-server-month | B39: =(B31*B32+B33)*B34*B35/B12 + B36*730*B37 + B38 -> 4331.2311 | C39: CHF/mo | D39: derived — compare with the Azure VM in B29
A41: Salaries — Zürich, gross + 15% employer cost, CHF per month
A42: Prompt engineer | B42: 9111 | C42: prompt | D42: Annex H.2, Table H2 — Robert Half 2026 median
A43: AI engineer | B43: 12698 | C43: ai | D43: Annex H.2, Table H2 — Robert Half 2026 median
A44: Application developer | B44: 12419 | C44: appdev | D44: Annex H.2, Table H2 — Robert Half 2026 median
A45: MLOps engineer | B45: 11174 | C45: mlops | D45: Annex H.2, Table H2 — Robert Half 2026 median
A46: Cloud engineer | B46: 13866 | C46: cloud | D46: Annex H.2, Table H2 — Robert Half 2026 median
...

Sheet Adoption
A1: Adoption and load, month by month
A2: Bass: F(t) = (1 - EXP(-(p+q)t)) / (1 + (q/p)EXP(-(p+q)t)), t measured in quarters. Phase 1 = early (<16%), 2 = mid (<84%), 3 = long-term.
A4: Month | B4: t (quarters) | C4: F(t) adopted | D4: Adopters | E4: Phase | F4: Answers / month | G4: Input tokens / month | H4: Output tokens / month | I4: Peak tokens / s | J4: GPU VMs needed
A5: 1 | B5: =(A5-0.5)/3 -> 0.16666667 | C5: =(1-EXP(-(Inputs!$B$15+Inputs!$B$16)*B5))/(1+(Inputs!$B$16/Inputs!$B$15)*EXP(-(Inputs!$B$15+Inputs!$B$16)*B5)) -> 0.0051481513 | D5: =MAX(ROUND(Inputs!$B$5*C5,0),1) -> 2 | E5: =IF(C5<0.16,1,IF(C5<0.84,2,3)) -> 1 | F5: =D5*Inputs!$B$6*Inputs!$B$9 -> 880 | G5: =D5*Inputs!$B$6*Inputs!$B$7*Inputs!$B$9 -> 4400000 | H5: =D5*Inputs!$B$6*Inputs!$B$8*Inputs!$B$9 -> 880000 | I5: =D5*Inputs!$B$6*(Inputs!$B$7+Inputs!$B$8)*Inputs!$B$11/Inputs!$B$10 -> 25 | J5: =MAX(1,CEILING(I5/Inputs!$B$30,1)) -> 1
A6: 2 | B6: =(A6-0.5)/3 -> 0.5 | C6: =(1-EXP(-(Inputs!$B$15+Inputs!$B$16)*B6))/(1+(Inputs!$B$16/Inputs!$B$15)*EXP(-(Inputs!$B$15+Inputs!$B$16)*B6)) -> 0.016375552 | D6: =MAX(ROUND(Inputs!$B$5*C6,0),1) -> 5 | E6: =IF(C6<0.16,1,IF(C6<0.84,2,3)) -> 1 | F6: =D6*Inputs!$B$6*Inputs!$B$9 -> 2200 | G6: =D6*Inputs!$B$6*Inputs!$B$7*Inputs!$B$9 -> 11000000 | H6: =D6*Inputs!$B$6*Inputs!$B$8*Inputs!$B$9 -> 2200000 | I6: =D6*Inputs!$B$6*(Inputs!$B$7+Inputs!$B$8)*Inputs!$B$11/Inputs!$B$10 -> 62.5 | J6: =MAX(1,CEILING(I6/Inputs!$B$30,1)) -> 1
A7: 3 | B7: =(A7-0.5)/3 -> 0.83333333 | C7: =(1-EXP(-(Inputs!$B$15+Inputs!$B$16)*B7))/(1+(Inputs!$B$16/Inputs!$B$15)*EXP(-(Inputs!$B$15+Inputs!$B$16)*B7)) -> 0.028939345 | D7: =MAX(ROUND(Inputs!$B$5*C7,0),1) -> 9 | E7: =IF(C7<0.16,1,IF(C7<0.84,2,3)) -> 1 | F7: =D7*Inputs!$B$6*Inputs!$B$9 -> 3960 | G7: =D7*Inputs!$B$6*Inputs!$B$7*Inputs!$B$9 -> 19800000 | H7: =D7*Inputs!$B$6*Inputs!$B$8*Inputs!$B$9 -> 3960000 | I7: =D7*Inputs!$B$6*(Inputs!$B$7+Inputs!$B$8)*Inputs!$B$11/Inputs!$B$10 -> 112.5 | J7: =MAX(1,CEILING(I7/Inputs!$B$30,1)) -> 1
A8: 4 | B8: =(A8-0.5)/3 -> 1.1666667 | C8: =(1-EXP(-(Inputs!$B$15+Inputs!$B$16)*B8))/(1+(Inputs!$B$16/Inputs!$B$15)*EXP(-(Inputs!$B$15+Inputs!$B$16)*B8)) -> 0.042953855 | D8: =MAX(ROUND(Inputs!$B$5*C8,0),1) -> 13 | E8: =IF(C8<0.16,1,IF(C8<0.84,2,3)) -> 1 | F8: =D8*Inputs!$B$6*Inputs!$B$9 -> 5720 | G8: =D8*Inputs!$B$6*Inputs!$B$7*Inputs!$B$9 -> 28600000 | H8: =D8*Inputs!$B$6*Inputs!$B$8*Inputs!$B$9 -> 5720000 | I8: =D8*Inputs!$B$6*(Inputs!$B$7+Inputs!$B$8)*Inputs!$B$11/Inputs!$B$10 -> 162.5 | J8: =MAX(1,CEILING(I8/Inputs!$B$30,1)) -> 1
A9: 5 | B9: =(A9-0.5)/3 -> 1.5 | C9: =(1-EXP(-(Inputs!$B$15+Inputs!$B$16)*B9))/(1+(Inputs!$B$16/Inputs!$B$15)*EXP(-(Inputs!$B$15+Inputs!$B$16)*B9)) -> 0.058531116 | D9: =MAX(ROUND(Inputs!$B$5*C9,0),1) -> 18 | E9: =IF(C9<0.16,1,IF(C9<0.84,2,3)) -> 1 | F9: =D9*Inputs!$B$6*Inputs!$B$9 -> 7920 | G9: =D9*Inputs!$B$6*Inputs!$B$7*Inputs!$B$9 -> 39600000 | H9: =D9*Inputs!$B$6*Inputs!$B$8*Inputs!$B$9 -> 7920000 | I9: =D9*Inputs!$B$6*(Inputs!$B$7+Inputs!$B$8)*Inputs!$B$11/Inputs!$B$10 -> 225 | J9: =MAX(1,CEILING(I9/Inputs!$B$30,1)) -> 1
A10: 6 | B10: =(A10-0.5)/3 -> 1.8333333 | C10: =(1-EXP(-(Inputs!$B$15+Inputs!$B$16)*B10))/(1+(Inputs!$B$16/Inputs!$B$15)*EXP(-(Inputs!$B$15+Inputs!$B$16)*B10)) -> 0.075777121 | D10: =MAX(ROUND(Inputs!$B$5*C10,0),1) -> 23 | E10: =IF(C10<0.16,1,IF(C10<0.84,2,3)) -> 1 | F10: =D10*Inputs!$B$6*Inputs!$B$9 -> 10120 | G10: =D10*Inputs!$B$6*Inputs!$B$7*Inputs!$B$9 -> 50600000 | H10: =D10*Inputs!$B$6*Inputs!$B$8*Inputs!$B$9 -> 10120000 | I10: =D10*Inputs!$B$6*(Inputs!$B$7+Inputs!$B$8)*Inputs!$B$11/Inputs!$B$10 -> 287.5 | J10: =MAX(1,CEILING(I10/Inputs!$B$30,1)) -> 1
A11: 7 | B11: =(A11-0.5)/3 -> 2.1666667 | C11: =(1-EXP(-(Inputs!$B$15+Inputs!$B$16)*B11))/(1+(Inputs!$B$16/Inputs!$B$15)*EXP(-(Inputs!$B$15+Inputs!$B$16)*B11)) -> 0.094787324 | D11: =MAX(ROUND(Inputs!$B$5*C11,0),1) -> 28 | E11: =IF(C11<0.16,1,IF(C11<0.84,2,3)) -> 1 | F11: =D11*Inputs!$B$6*Inputs!$B$9 -> 12320 | G11: =D11*Inputs!$B$6*Inputs!$B$7*Inputs!$B$9 -> 61600000 | H11: =D11*Inputs!$B$6*Inputs!$B$8*Inputs!$B$9 -> 12320000 | I11: =D11*Inputs!$B$6*(Inputs!$B$7+Inputs!$B$8)*Inputs!$B$11/Inputs!$B$10 -> 350 | J11: =MAX(1,CEILING(I11/Inputs!$B$30,1)) -> 1
A12: 8 | B12: =(A12-0.5)/3 -> 2.5 | C12: =(1-EXP(-(Inputs!$B$15+Inputs!$B$16)*B12))/(1+(Inputs!$B$16/Inputs!$B$15)*EXP(-(Inputs!$B$15+Inputs!$B$16)*B12)) -> 0.11564145 | D12: =MAX(ROUND(Inputs!$B$5*C12,0),1) -> 35 | E12: =IF(C12<0.16,1,IF(C12<0.84,2,3)) -> 1 | F12: =D12*Inputs!$B$6*Inputs!$B$9 -> 15400 | G12: =D12*Inputs!$B$6*Inputs!$B$7*Inputs!$B$9 -> 77000000 | H12: =D12*Inputs!$B$6*Inputs!$B$8*Inputs!$B$9 -> 15400000 | I12: =D12*Inputs!$B$6*(Inputs!$B$7+Inputs!$B$8)*Inputs!$B$11/Inputs!$B$10 -> 437.5 | J12: =MAX(1,CEILING(I12/Inputs!$B$30,1)) -> 1
A13: 9 | B13: =(A13-0.5)/3 -> 2.8333333 | C13: =(1-EXP(-(Inputs!$B$15+Inputs!$B$16)*B13))/(1+(Inputs!$B$16/Inputs!$B$15)*EXP(-(Inputs!$B$15+Inputs!$B$16)*B13)) -> 0.13839776 | D13: =MAX(ROUND(Inputs!$B$5*C13,0),1) -> 42 | E13: =IF(C13<0.16,1,IF(C13<0.84,2,3)) -> 1 | F13: =D13*Inputs!$B$6*Inputs!$B$9 -> 18480 | G13: =D13*Inputs!$B$6*Inputs!$B$7*Inputs!$B$9 -> 92400000 | H13: =D13*Inputs!$B$6*Inputs!$B$8*Inputs!$B$9 -> 18480000 | I13: =D13*Inputs!$B$6*(Inputs!$B$7+Inputs!$B$8)*Inputs!$B$11/Inputs!$B$10 -> 525 | J13: =MAX(1,CEILING(I13/Inputs!$B$30,1)) -> 1
A14: 10 | B14: =(A14-0.5)/3 -> 3.1666667 | C14: =(1-EXP(-(Inputs!$B$15+Inputs!$B$16)*B14))/(1+(Inputs!$B$16/Inputs!$B$15)*EXP(-(Inputs!$B$15+Inputs!$B$16)*B14)) -> 0.16308697 | D14: =MAX(ROUND(Inputs!$B$5*C14,0),1) -> 49 | E14: =IF(C14<0.16,1,IF(C14<0.84,2,3)) -> 2 | F14: =D14*Inputs!$B$6*Inputs!$B$9 -> 21560 | G14: =D14*Inputs!$B$6*Inputs!$B$7*Inputs!$B$9 -> 107800000 | H14: =D14*Inputs!$B$6*Inputs!$B$8*Inputs!$B$9 -> 21560000 | I14: =D14*Inputs!$B$6*(Inputs!$B$7+Inputs!$B$8)*Inputs!$B$11/Inputs!$B$10 -> 612.5 | J14: =MAX(1,CEILING(I14/Inputs!$B$30,1)) -> 1
A15: 11 | B15: =(A15-0.5)/3 -> 3.5 | C15: =(1-EXP(-(Inputs!$B$15+Inputs!$B$16)*B15))/(1+(Inputs!$B$16/Inputs!$B$15)*EXP(-(Inputs!$B$15+Inputs!$B$16)*B15)) -> 0.18970627 | D15: =MAX(ROUND(Inputs!$B$5*C15,0),1) -> 57 | E15: =IF(C15<0.16,1,IF(C15<0.84,2,3)) -> 2 | F15: =D15*Inputs!$B$6*Inputs!$B$9 -> 25080 | G15: =D15*Inputs!$B$6*Inputs!$B$7*Inputs!$B$9 -> 125400000 | H15: =D15*Inputs!$B$6*Inputs!$B$8*Inputs!$B$9 -> 25080000 | I15: =D15*Inputs!$B$6*(Inputs!$B$7+Inputs!$B$8)*Inputs!$B$11/Inputs!$B$10 -> 712.5 | J15: =MAX(1,CEILING(I15/Inputs!$B$30,1)) -> 1
A16: 12 | B16: =(A16-0.5)/3 -> 3.8333333 | C16: =(1-EXP(-(Inputs!$B$15+Inputs!$B$16)*B16))/(1+(Inputs!$B$16/Inputs!$B$15)*EXP(-(Inputs!$B$15+Inputs!$B$16)*B16)) -> 0.21821368 | D16: =MAX(ROUND(Inputs!$B$5*C16,0),1) -> 65 | E16: =IF(C16<0.16,1,IF(C16<0.84,2,3)) -> 2 | F16: =D16*Inputs!$B$6*Inputs!$B$9 -> 28600 | G16: =D16*Inputs!$B$6*Inputs!$B$7*Inputs!$B$9 -> 143000000 | H16: =D16*Inputs!$B$6*Inputs!$B$8*Inputs!$B$9 -> 28600000 | I16: =D16*Inputs!$B$6*(Inputs!$B$7+Inputs!$B$8)*Inputs!$B$11/Inputs!$B$10 -> 812.5 | J16: =MAX(1,CEILING(I16/Inputs!$B$30,1)) -> 1
... A40: 36 | B40: =(A40-0.5)/3 -> 11.833333 | C40: =(1-EXP(-(Inputs!$B$15+Inputs!$B$16)*B40))/(1+(Inputs!$B$16/Inputs!$B$15)*EXP(-(Inputs!$B$15+Inputs!$B$16)*B40)) -> 0.90281145 | D40: =MAX(ROUND(Inputs!$B$5*C40,0),1) -> 271 | E40: =IF(C40<0.16,1,IF(C40<0.84,2,3)) -> 3 | F40: =D40*Inputs!$B$6*Inputs!$B$9 -> 119240 | G40: =D40*Inputs!$B$6*Inputs!$B$7*Inputs!$B$9 -> 596200000 | H40: =D40*Inputs!$B$6*Inputs!$B$8*Inputs!$B$9 -> 119240000 | I40: =D40*Inputs!$B$6*(Inputs!$B$7+Inputs!$B$8)*Inputs!$B$11/Inputs!$B$10 -> 3387.5 | J40: =MAX(1,CEILING(I40/Inputs!$B$30,1)) -> 2
A42: GPU VMs are sized on the PEAK rate, not the average: a VM that serves 2,400 tokens/s at peak delivers only about 507M tokens a month when the load runs for eight hours with a 3x peak.

Sheet Monthly cost
A1: Monthly cost of the same use case on each infrastructure, CHF
A2: Service = subscription or tokens. Infra = cloud or on-premises capacity. Workforce = the people who build and run it. One-time setup is added once, on the Summary sheet.
B3: AI as a Service | E3: GenAI Gateway | H3: Hyperscaled AI | K3: Owned AI
A4: Month | B4: Service | C4: Infra | D4: Workforce | E4: Service | F4: Infra | G4: Workforce | H4: Service | I4: Infra | J4: Workforce | K4: Service | L4: Infra | M4: Workforce
A5: 1 | B5: =Inputs!$B$19*Inputs!$B$5 + CEILING(Adoption!F5*Inputs!$B$20/Inputs!$B$21,1)*Inputs!$B$22 -> 7666 | C5: 0 | D5: =INDEX(Inputs!$C$67:$E$67,Adoption!E5) -> 2733.3 | E5: =Adoption!G5/1000000*Inputs!$B$25 + Adoption!H5/1000000*Inputs!$B$26 -> 20.1344 | F5: 0 | G5: =INDEX(Inputs!$C$68:$E$68,Adoption!E5) -> 6265.3 | H5: 0 | I5: =Adoption!J5*Inputs!$B$29 -> 12126 | J5: =INDEX(Inputs!$C$69:$E$69,Adoption!E5) -> 17198.2 | K5: 0 | L5: =Adoption!J5*Inputs!$B$39 -> 4331.2311 | M5: =INDEX(Inputs!$C$70:$E$70,Adoption!E5) -> 15522.2
A6: 2 | B6: =Inputs!$B$19*Inputs!$B$5 + CEILING(Adoption!F6*Inputs!$B$20/Inputs!$B$21,1)*Inputs!$B$22 -> 7666 | C6: 0 | D6: =INDEX(Inputs!$C$67:$E$67,Adoption!E6) -> 2733.3 | E6: =Adoption!G6/1000000*Inputs!$B$25 + Adoption!H6/1000000*Inputs!$B$26 -> 50.336 | F6: 0 | G6: =INDEX(Inputs!$C$68:$E$68,Adoption!E6) -> 6265.3 | H6: 0 | I6: =Adoption!J6*Inputs!$B$29 -> 12126 | J6: =INDEX(Inputs!$C$69:$E$69,Adoption!E6) -> 17198.2 | K6: 0 | L6: =Adoption!J6*Inputs!$B$39 -> 4331.2311 | M6: =INDEX(Inputs!$C$70:$E$70,Adoption!E6) -> 15522.2
A7: 3 | B7: =Inputs!$B$19*Inputs!$B$5 + CEILING(Adoption!F7*Inputs!$B$20/Inputs!$B$21,1)*Inputs!$B$22 -> 7832 | C7: 0 | D7: =INDEX(Inputs!$C$67:$E$67,Adoption!E7) -> 2733.3 | E7: =Adoption!G7/1000000*Inputs!$B$25 + Adoption!H7/1000000*Inputs!$B$26 -> 90.6048 | F7: 0 | G7: =INDEX(Inputs!$C$68:$E$68,Adoption!E7) -> 6265.3 | H7: 0 | I7: =Adoption!J7*Inputs!$B$29 -> 12126 | J7: =INDEX(Inputs!$C$69:$E$69,Adoption!E7) -> 17198.2 | K7: 0 | L7: =Adoption!J7*Inputs!$B$39 -> 4331.2311 | M7: =INDEX(Inputs!$C$70:$E$70,Adoption!E7) -> 15522.2
A8: 4 | B8: =Inputs!$B$19*Inputs!$B$5 + CEILING(Adoption!F8*Inputs!$B$20/Inputs!$B$21,1)*Inputs!$B$22 -> 7998 | C8: 0 | D8: =INDEX(Inputs!$C$67:$E$67,Adoption!E8) -> 2733.3 | E8: =Adoption!G8/1000000*Inputs!$B$25 + Adoption!H8/1000000*Inputs!$B$26 -> 130.8736 | F8: 0 | G8: =INDEX(Inputs!$C$68:$E$68,Adoption!E8) -> 6265.3 | H8: 0 | I8: =Adoption!J8*Inputs!$B$29 -> 12126 | J8: =INDEX(Inputs!$C$69:$E$69,Adoption!E8) -> 17198.2 | K8: 0 | L8: =Adoption!J8*Inputs!$B$39 -> 4331.2311 | M8: =INDEX(Inputs!$C$70:$E$70,Adoption!E8) -> 15522.2
A9: 5 | B9: =Inputs!$B$19*Inputs!$B$5 + CEILING(Adoption!F9*Inputs!$B$20/Inputs!$B$21,1)*Inputs!$B$22 -> 8164 | C9: 0 | D9: =INDEX(Inputs!$C$67:$E$67,Adoption!E9) -> 2733.3 | E9: =Adoption!G9/1000000*Inputs!$B$25 + Adoption!H9/1000000*Inputs!$B$26 -> 181.2096 | F9: 0 | G9: =INDEX(Inputs!$C$68:$E$68,Adoption!E9) -> 6265.3 | H9: 0 | I9: =Adoption!J9*Inputs!$B$29 -> 12126 | J9: =INDEX(Inputs!$C$69:$E$69,Adoption!E9) -> 17198.2 | K9: 0 | L9: =Adoption!J9*Inputs!$B$39 -> 4331.2311 | M9: =INDEX(Inputs!$C$70:$E$70,Adoption!E9) -> 15522.2
A10: 6 | B10: =Inputs!$B$19*Inputs!$B$5 + CEILING(Adoption!F10*Inputs!$B$20/Inputs!$B$21,1)*Inputs!$B$22 -> 8330 | C10: 0 | D10: =INDEX(Inputs!$C$67:$E$67,Adoption!E10) -> 2733.3 | E10: =Adoption!G10/1000000*Inputs!$B$25 + Adoption!H10/1000000*Inputs!$B$26 -> 231.5456 | F10: 0 | G10: =INDEX(Inputs!$C$68:$E$68,Adoption!E10) -> 6265.3 | H10: 0 | I10: =Adoption!J10*Inputs!$B$29 -> 12126 | J10: =INDEX(Inputs!$C$69:$E$69,Adoption!E10) -> 17198.2 | K10: 0 | L10: =Adoption!J10*Inputs!$B$39 -> 4331.2311 | M10: =INDEX(Inputs!$C$70:$E$70,Adoption!E10) -> 15522.2
A11: 7 | B11: =Inputs!$B$19*Inputs!$B$5 + CEILING(Adoption!F11*Inputs!$B$20/Inputs!$B$21,1)*Inputs!$B$22 -> 8330 | C11: 0 | D11: =INDEX(Inputs!$C$67:$E$67,Adoption!E11) -> 2733.3 | E11: =Adoption!G11/1000000*Inputs!$B$25 + Adoption!H11/1000000*Inputs!$B$26 -> 281.8816 | F11: 0 | G11: =INDEX(Inputs!$C$68:$E$68,Adoption!E11) -> 6265.3 | H11: 0 | I11: =Adoption!J11*Inputs!$B$29 -> 12126 | J11: =INDEX(Inputs!$C$69:$E$69,Adoption!E11) -> 17198.2 | K11: 0 | L11: =Adoption!J11*Inputs!$B$39 -> 4331.2311 | M11: =INDEX(Inputs!$C$70:$E$70,Adoption!E11) -> 15522.2
A12: 8 | B12: =Inputs!$B$19*Inputs!$B$5 + CEILING(Adoption!F12*Inputs!$B$20/Inputs!$B$21,1)*Inputs!$B$22 -> 8662 | C12: 0 | D12: =INDEX(Inputs!$C$67:$E$67,Adoption!E12) -> 2733.3 | E12: =Adoption!G12/1000000*Inputs!$B$25 + Adoption!H12/1000000*Inputs!$B$26 -> 352.352 | F12: 0 | G12: =INDEX(Inputs!$C$68:$E$68,Adoption!E12) -> 6265.3 | H12: 0 | I12: =Adoption!J12*Inputs!$B$29 -> 12126 | J12: =INDEX(Inputs!$C$69:$E$69,Adoption!E12) -> 17198.2 | K12: 0 | L12: =Adoption!J12*Inputs!$B$39 -> 4331.2311 | M12: =INDEX(Inputs!$C$70:$E$70,Adoption!E12) -> 15522.2
A13: 9 | B13: =Inputs!$B$19*Inputs!$B$5 + CEILING(Adoption!F13*Inputs!$B$20/Inputs!$B$21,1)*Inputs!$B$22 -> 8828 | C13: 0 | D13: =INDEX(Inputs!$C$67:$E$67,Adoption!E13) -> 2733.3 | E13: =Adoption!G13/1000000*Inputs!$B$25 + Adoption!H13/1000000*Inputs!$B$26 -> 422.8224 | F13: 0 | G13: =INDEX(Inputs!$C$68:$E$68,Adoption!E13) -> 6265.3 | H13: 0 | I13: =Adoption!J13*Inputs!$B$29 -> 12126 | J13: =INDEX(Inputs!$C$69:$E$69,Adoption!E13) -> 17198.2 | K13: 0 | L13: =Adoption!J13*Inputs!$B$39 -> 4331.2311 | M13: =INDEX(Inputs!$C$70:$E$70,Adoption!E13) -> 15522.2
A14: 10 | B14: =Inputs!$B$19*Inputs!$B$5 + CEILING(Adoption!F14*Inputs!$B$20/Inputs!$B$21,1)*Inputs!$B$22 -> 8994 | C14: 0 | D14: =INDEX(Inputs!$C$67:$E$67,Adoption!E14) -> 2733.3 | E14: =Adoption!G14/1000000*Inputs!$B$25 + Adoption!H14/1000000*Inputs!$B$26 -> 493.2928 | F14: 0 | G14: =INDEX(Inputs!$C$68:$E$68,Adoption!E14) -> 11288.7 | H14: 0 | I14: =Adoption!J14*Inputs!$B$29 -> 12126 | J14: =INDEX(Inputs!$C$69:$E$69,Adoption!E14) -> 27173.8 | K14: 0 | L14: =Adoption!J14*Inputs!$B$39 -> 4331.2311 | M14: =INDEX(Inputs!$C$70:$E$70,Adoption!E14) -> 26450.3
A15: 11 | B15: =Inputs!$B$19*Inputs!$B$5 + CEILING(Adoption!F15*Inputs!$B$20/Inputs!$B$21,1)*Inputs!$B$22 -> 9326 | C15: 0 | D15: =INDEX(Inputs!$C$67:$E$67,Adoption!E15) -> 2733.3 | E15: =Adoption!G15/1000000*Inputs!$B$25 + Adoption!H15/1000000*Inputs!$B$26 -> 573.8304 | F15: 0 | G15: =INDEX(Inputs!$C$68:$E$68,Adoption!E15) -> 11288.7 | H15: 0 | I15: =Adoption!J15*Inputs!$B$29 -> 12126 | J15: =INDEX(Inputs!$C$69:$E$69,Adoption!E15) -> 27173.8 | K15: 0 | L15: =Adoption!J15*Inputs!$B$39 -> 4331.2311 | M15: =INDEX(Inputs!$C$70:$E$70,Adoption!E15) -> 26450.3
A16: 12 | B16: =Inputs!$B$19*Inputs!$B$5 + CEILING(Adoption!F16*Inputs!$B$20/Inputs!$B$21,1)*Inputs!$B$22 -> 9492 | C16: 0 | D16: =INDEX(Inputs!$C$67:$E$67,Adoption!E16) -> 2733.3 | E16: =Adoption!G16/1000000*Inputs!$B$25 + Adoption!H16/1000000*Inputs!$B$26 -> 654.368 | F16: 0 | G16: =INDEX(Inputs!$C$68:$E$68,Adoption!E16) -> 11288.7 | H16: 0 | I16: =Adoption!J16*Inputs!$B$29 -> 12126 | J16: =INDEX(Inputs!$C$69:$E$69,Adoption!E16) -> 27173.8 | K16: 0 | L16: =Adoption!J16*Inputs!$B$39 -> 4331.2311 | M16: =INDEX(Inputs!$C$70:$E$70,Adoption!E16) -> 26450.3
... A40: 36 | B40: =Inputs!$B$19*Inputs!$B$5 + CEILING(Adoption!F40*Inputs!$B$20/Inputs!$B$21,1)*Inputs!$B$22 -> 15468 | C40: 0 | D40: =INDEX(Inputs!$C$67:$E$67,Adoption!E40) -> 2733.3 | E40: =Adoption!G40/1000000*Inputs!$B$25 + Adoption!H40/1000000*Inputs!$B$26 -> 2728.2112 | F40: 0 | G40: =INDEX(Inputs!$C$68:$E$68,Adoption!E40) -> 12558.5 | H40: 0 | I40: =Adoption!J40*Inputs!$B$29 -> 24252 | J40: =INDEX(Inputs!$C$69:$E$69,Adoption!E40) -> 36735.5 | K40: 0 | L40: =Adoption!J40*Inputs!$B$39 -> 8662.4622 | M40: =INDEX(Inputs!$C$70:$E$70,Adoption!E40) -> 36012

Sheet Summary
A1: Three-year total cost of ownership — the four bars of slide 13
A2: Every figure below is the sum of the 'Monthly cost' sheet plus the one-time setup from Inputs.
A4: Infrastructure model | B4: Service | C4: Infrastructure | D4: Workforce — run | E4: Workforce — setup | F4: TOTAL | G4: What the number is
A5: AI as a Service | B5: =SUM('Monthly cost'!B5:B40) -> 413922 | C5: =SUM('Monthly cost'!C5:C40) -> 0 | D5: =SUM('Monthly cost'!D5:D40) -> 98398.8 | E5: =Inputs!$F$67 -> 9111 | F5: =SUM(B5:E5) -> 521431.8 | G5: 300 Copilot seats at CHF 25/month for 36 months = CHF 270,000, plus credit packs at 10 credits per answer
A6: GenAI Gateway | B6: =SUM('Monthly cost'!E5:E40) -> 48503.77 | C6: =SUM('Monthly cost'!F5:F40) -> 0 | D6: =SUM('Monthly cost'!G5:G40) -> 367531.6 | E6: =Inputs!$F$68 -> 37535 | F6: =SUM(B6:E6) -> 453570.37 | G6: GPT-5.4 tokens: 10.6bn input at 2.08 and 2.1bn output at 12.48 per million
A7: Hyperscaled AI | B7: =SUM('Monthly cost'!H5:H40) -> 0 | C7: =SUM('Monthly cost'!I5:I40) -> 582048 | D7: =SUM('Monthly cost'!J5:J40) -> 936284.9 | E7: =Inputs!$F$69 -> 73470 | F7: =SUM(B7:E7) -> 1591802.9 | G7: 48 VM-months of NC80adis H100 v5 at CHF 12,126, always on
A8: Owned AI | B8: =SUM('Monthly cost'!K5:K40) -> 0 | C8: =SUM('Monthly cost'!L5:L40) -> 207899.09 | D8: =SUM('Monthly cost'!M5:M40) -> 901666.4 | E8: =Inputs!$F$70 -> 59605 | F8: =SUM(B8:E8) -> 1169170.5 | G8: 48 server-months at the hardware build-up in Inputs!B39 — card price, APEX term, power, colocation
A9: Share that is people | B9: =(D5+E5)/F5 -> 0.2061819 | C9: =(D6+E6)/F6 -> 0.89306231 | D9: =(D7+E7)/F7 -> 0.63434669 | E9: =(D8+E8)/F8 -> 0.8221824
B10: AI as a Service | C10: GenAI Gateway | D10: Hyperscaled AI | E10: Owned AI
A13: What is NOT in these numbers — state these before anyone asks
A15: 1. Copilot Credits are charged at 10 per answer (Inputs!B20), the tenant-graph grounding rate of Annex B Table B1, because this agent is grounded on guidelines and past cases. At the bare generative-answer rate of 2 credits, AI as a Service would fall to about CHF 409,000.
A16: 2. Hyperscaled and Owned AI run the same open-source stack on their own machines, so there is no separate Azure bill for a vector database or a model endpoint. Storage and network on top of the VM are not costed; both bars are understated by that amount, Hyperscaled slightly more than Owned.
A17: 3. Owned AI hardware is built up from a card price, not assumed as a share of Azure: USD 29,000 per H100 NVL (TRG Datacenters, October 2026) plus a chassis, over the 36-month term, with a 1.4x subscription uplift for APEX, plus power and Swisscom colocation. The uplift and the chassis price are the two estimates left in it.
A18: 4. The Copilot seat is charged to this application in full. If these 300 users are already licensed for other reasons, the marginal cost of the application is the credits alone and AI as a Service falls to about CHF 139,000.
A19: 5. Salaries, FTE fractions, setup effort and the adoption coefficients are reasoned assumptions, not values validated with practitioners (Annexes F.4 and H.6).
A20: 6. One application carrying a whole platform team. A portfolio sharing that team changes every conclusion.
A21: 7. Owned AI carries no infrastructure engineer: Dell maintains the hardware under the APEX subscription and Swisscom provides the data-centre layer with the colocation. Its setup falls to 5 person-months accordingly.
